Workbook

Sheet Kapsam Modeli
A1: Dış Gündem — Kaynak Havuzu v2 (çok ülkeli)
A2: Hazırlanma: 18 Ekim 2026. Claude'un genel bilgisine dayanan başlangıç taslağı; URL/RSS/aktiflik doğrulanmadan hatta alınmamalı.
A4: KAPSAM SEVİYELERİ
A5: A — Yakın çevre (iç gündem + Türkiye) | B5: Bu ülkelerin kritik/önemli İÇ haberleri de kapsamda: iktidar/seçim, güvenlik ve çatışma, ekonomi/kriz, dış politika kararları, enerji. Artı Türkiye ile ilgili her şey. Kaynak: ülkenin 4-7 ana ulusal yayını + ajans + 1 think tank. İç haber için LLM 'önem skoru' (1-5) uygulanır; eşik altı yayınlanmaz.
A6: B — Türkiye'ye bakış | B6: Yalnızca Türkiye'yi konu alan içerik: anahtar kelime filtresi (bkz. 'Türkiye Terimleri') + LLM doğrulama. Kaynak: ülkenin 2-4 ağırlıklı yayını + Türkiye programı olan think tank'ler + Google News ülke/dil filtresi.
A7: R — Bölgesel | B7: Birden fazla ülkeye hizmet eden yayınlar (Al-Monitor, Eurasianet, JAMnews…). Hem A hem B rolünde çalışır; ülke etiketi makale bazında atanır.
A8: T — Türk perspektifi | B8: Resmi Türk pozisyonu ve Türk think tank'leri. Her ülke sayfasında 'Ankara ne dedi' kutusunu besler.
A9: P — Premium | B9: FT, Bloomberg, WSJ, Economist, Foreign Affairs, Foreign Policy. Gmail bültenleri; kendi analizinle süzülerek 'Analiz' içerik tipinde kullanılır, haber kartı olmaz.
A11: THINK TANK KATMANI | B11: Her bölge için yerel think tank'ler + Türk think tank'leri (ORSAM, SETA, EDAM, TEPAV, İRAM, AVİM, İKV…) havuzda; 'Tür' sütununda "Think tank" filtresiyle görünür. Rolü: haber değil, 'Analiz' içerik tipinin hammaddesi; haftalık tarama yeterli, saatlik değil.
A12: BÖLGELER (site navigasyonu) | B12: Levant & Irak · Doğu Akdeniz · Körfez & İran · Kafkasya · Karadeniz & Rusya · Avrupa · Kuzey Amerika · Asya · Afrika. Orta Asya ve Balkanlar bu sürümde yok; ikinci fazda eklenir.
A14: SÜTUNLAR
A15: İçerik rolü | B15: İç gündem + Türkiye = A kapsamı · Türkiye'ye bakış = B kapsamı · Bölgesel · Türk perspektifi · Premium bağlam
A16: Güvenilirlik | B16: A bağımsız/kurumsal · B ana akım ama devlet/sermaye/siyasi eksene yakın · C devlet ajansı/propaganda — 'resmi pozisyon' etiketiyle, haber olarak değil
A17: Durum | B17: Çekirdek = ilk günden takip (yeşil) · Kontrol et = doğrulanmadı (sarı) · Pasif/Çıkarıldı
A18: Sarı hücreler | B18: Doldurulacak/doğrulanacak: RSS URL ve Durum. İlk 2 haftalık toplama verisiyle envanter budanır.
A20: İÇ GÜNDEM 'ÖNEM' ÖLÇÜTÜ (A kapsamı için LLM talimatı özeti) | B20: 5 = rejim/iktidar değişimi, savaş-barış kararı, büyük saldırı · 4 = seçim sonucu, hükümet krizi, büyük ekonomik şok, Türkiye'yi doğrudan ilgilendiren karar · 3 = kabine değişikliği, önemli yargı kararı, enerji/altyapı anlaşması · 2 = rutin siyaset · 1 = magazin/yerel. Eşik: ≥3 yayınlanır, ≥4 ana sayfaya çıkar.

Sheet Özet
A1: Kaynak havuzu özeti (canlı formüller)
A3: Toplam kaynak | B3: =COUNTA('Kaynak Havuzu'!A:A)-1 -> 259
A4: Çekirdek | B4: =COUNTIF('Kaynak Havuzu'!N:N,"Çekirdek") -> 114
A5: Kontrol et | B5: =COUNTIF('Kaynak Havuzu'!N:N,"Kontrol et") -> 145
A6: RSS seçili, URL boş | B6: =COUNTIFS('Kaynak Havuzu'!L:L,"RSS",'Kaynak Havuzu'!M:M,"") -> 202
A7: Think tank (toplam / çekirdek) | B7: =COUNTIF('Kaynak Havuzu'!H:H,"Think tank") -> 111 | C7: =COUNTIFS('Kaynak Havuzu'!H:H,"Think tank",'Kaynak Havuzu'!N:N,"Çekirdek") -> 38
A8: Kapsam | B8: Toplam | C8: Çekirdek | E8: Bölge | F8: Toplam | G8: Çekirdek | I8: Ülke | J8: Toplam | K8: Çekirdek
A9: A — Yakın çevre | B9: =COUNTIF('Kaynak Havuzu'!B:B,"A") -> 112 | C9: =COUNTIFS('Kaynak Havuzu'!B:B,"A",'Kaynak Havuzu'!N:N,"Çekirdek") -> 54 | E9: Levant & Irak | F9: =COUNTIF('Kaynak Havuzu'!C:C,"Levant & Irak") -> 24 | G9: =COUNTIFS('Kaynak Havuzu'!C:C,"Levant & Irak",'Kaynak Havuzu'!N:N,"Çekirdek") -> 12 | I9: Suriye | J9: =COUNTIF('Kaynak Havuzu'!D:D,"Suriye") -> 10 | K9: =COUNTIFS('Kaynak Havuzu'!D:D,"Suriye",'Kaynak Havuzu'!N:N,"Çekirdek") -> 7
A10: B — Türkiye'ye bakış | B10: =COUNTIF('Kaynak Havuzu'!B:B,"B") -> 90 | C10: =COUNTIFS('Kaynak Havuzu'!B:B,"B",'Kaynak Havuzu'!N:N,"Çekirdek") -> 31 | E10: Doğu Akdeniz | F10: =COUNTIF('Kaynak Havuzu'!C:C,"Doğu Akdeniz") -> 37 | G10: =COUNTIFS('Kaynak Havuzu'!C:C,"Doğu Akdeniz",'Kaynak Havuzu'!N:N,"Çekirdek") -> 17 | I10: Irak | J10: =COUNTIF('Kaynak Havuzu'!D:D,"Irak") -> 10 | K10: =COUNTIFS('Kaynak Havuzu'!D:D,"Irak",'Kaynak Havuzu'!N:N,"Çekirdek") -> 4
A11: R — Bölgesel | B11: =COUNTIF('Kaynak Havuzu'!B:B,"R") -> 26 | C11: =COUNTIFS('Kaynak Havuzu'!B:B,"R",'Kaynak Havuzu'!N:N,"Çekirdek") -> 13 | E11: Körfez & İran | F11: =COUNTIF('Kaynak Havuzu'!C:C,"Körfez & İran") -> 30 | G11: =COUNTIFS('Kaynak Havuzu'!C:C,"Körfez & İran",'Kaynak Havuzu'!N:N,"Çekirdek") -> 14 | I11: İsrail | J11: =COUNTIF('Kaynak Havuzu'!D:D,"İsrail") -> 11 | K11: =COUNTIFS('Kaynak Havuzu'!D:D,"İsrail",'Kaynak Havuzu'!N:N,"Çekirdek") -> 7
A12: T — Türk perspektifi | B12: =COUNTIF('Kaynak Havuzu'!B:B,"T") -> 22 | C12: =COUNTIFS('Kaynak Havuzu'!B:B,"T",'Kaynak Havuzu'!N:N,"Çekirdek") -> 8 | E12: Kafkasya | F12: =COUNTIF('Kaynak Havuzu'!C:C,"Kafkasya") -> 23 | G12: =COUNTIFS('Kaynak Havuzu'!C:C,"Kafkasya",'Kaynak Havuzu'!N:N,"Çekirdek") -> 13 | I12: Yunanistan | J12: =COUNTIF('Kaynak Havuzu'!D:D,"Yunanistan") -> 9 | K12: =COUNTIFS('Kaynak Havuzu'!D:D,"Yunanistan",'Kaynak Havuzu'!N:N,"Çekirdek") -> 3
A13: P — Premium/Küresel | B13: =COUNTIF('Kaynak Havuzu'!B:B,"P") -> 9 | C13: =COUNTIFS('Kaynak Havuzu'!B:B,"P",'Kaynak Havuzu'!N:N,"Çekirdek") -> 8 | E13: Karadeniz & Rusya | F13: =COUNTIF('Kaynak Havuzu'!C:C,"Karadeniz & Rusya") -> 25 | G13: =COUNTIFS('Kaynak Havuzu'!C:C,"Karadeniz & Rusya",'Kaynak Havuzu'!N:N,"Çekirdek") -> 11 | I13: GKRY | J13: =COUNTIF('Kaynak Havuzu'!D:D,"GKRY") -> 6 | K13: =COUNTIFS('Kaynak Havuzu'!D:D,"GKRY",'Kaynak Havuzu'!N:N,"Çekirdek") -> 3
E14: Avrupa | F14: =COUNTIF('Kaynak Havuzu'!C:C,"Avrupa") -> 30 | G14: =COUNTIFS('Kaynak Havuzu'!C:C,"Avrupa",'Kaynak Havuzu'!N:N,"Çekirdek") -> 13 | I14: Mısır | J14: =COUNTIF('Kaynak Havuzu'!D:D,"Mısır") -> 8 | K14: =COUNTIFS('Kaynak Havuzu'!D:D,"Mısır",'Kaynak Havuzu'!N:N,"Çekirdek") -> 3
E15: Kuzey Amerika | F15: =COUNTIF('Kaynak Havuzu'!C:C,"Kuzey Amerika") -> 22 | G15: =COUNTIFS('Kaynak Havuzu'!C:C,"Kuzey Amerika",'Kaynak Havuzu'!N:N,"Çekirdek") -> 5 | I15: İran | J15: =COUNTIF('Kaynak Havuzu'!D:D,"İran") -> 10 | K15: =COUNTIFS('Kaynak Havuzu'!D:D,"İran",'Kaynak Havuzu'!N:N,"Çekirdek") -> 4
E16: Asya | F16: =COUNTIF('Kaynak Havuzu'!C:C,"Asya") -> 22 | G16: =COUNTIFS('Kaynak Havuzu'!C:C,"Asya",'Kaynak Havuzu'!N:N,"Çekirdek") -> 7 | I16: Suudi Arabistan | J16: =COUNTIF('Kaynak Havuzu'!D:D,"Suudi Arabistan") -> 9 | K16: =COUNTIFS('Kaynak Havuzu'!D:D,"Suudi Arabistan",'Kaynak Havuzu'!N:N,"Çekirdek") -> 3
E17: Afrika | F17: =COUNTIF('Kaynak Havuzu'!C:C,"Afrika") -> 16 | G17: =COUNTIFS('Kaynak Havuzu'!C:C,"Afrika",'Kaynak Havuzu'!N:N,"Çekirdek") -> 6 | I17: Azerbaycan | J17: =COUNTIF('Kaynak Havuzu'!D:D,"Azerbaycan") -> 9 | K17: =COUNTIFS('Kaynak Havuzu'!D:D,"Azerbaycan",'Kaynak Havuzu'!N:N,"Çekirdek") -> 5
E18: Türkiye | F18: =COUNTIF('Kaynak Havuzu'!C:C,"Türkiye") -> 21 | G18: =COUNTIFS('Kaynak Havuzu'!C:C,"Türkiye",'Kaynak Havuzu'!N:N,"Çekirdek") -> 8 | I18: Ermenistan | J18: =COUNTIF('Kaynak Havuzu'!D:D,"Ermenistan") -> 9 | K18: =COUNTIFS('Kaynak Havuzu'!D:D,"Ermenistan",'Kaynak Havuzu'!N:N,"Çekirdek") -> 5
E19: Küresel | F19: =COUNTIF('Kaynak Havuzu'!C:C,"Küresel") -> 9 | G19: =COUNTIFS('Kaynak Havuzu'!C:C,"Küresel",'Kaynak Havuzu'!N:N,"Çekirdek") -> 8 | I19: Rusya | J19: =COUNTIF('Kaynak Havuzu'!D:D,"Rusya") -> 12 | K19: =COUNTIFS('Kaynak Havuzu'!D:D,"Rusya",'Kaynak Havuzu'!N:N,"Çekirdek") -> 6
I20: Ukrayna | J20: =COUNTIF('Kaynak Havuzu'!D:D,"Ukrayna") -> 9 | K20: =COUNTIFS('Kaynak Havuzu'!D:D,"Ukrayna",'Kaynak Havuzu'!N:N,"Çekirdek") -> 4
I21: AB | J21: =COUNTIF('Kaynak Havuzu'!D:D,"AB") -> 13 | K21: =COUNTIFS('Kaynak Havuzu'!D:D,"AB",'Kaynak Havuzu'!N:N,"Çekirdek") -> 6
I22: ABD | J22: =COUNTIF('Kaynak Havuzu'!D:D,"ABD") -> 22 | K22: =COUNTIFS('Kaynak Havuzu'!D:D,"ABD",'Kaynak Havuzu'!N:N,"Çekirdek") -> 5
I23: Çin | J23: =COUNTIF('Kaynak Havuzu'!D:D,"Çin") -> 10 | K23: =COUNTIFS('Kaynak Havuzu'!D:D,"Çin",'Kaynak Havuzu'!N:N,"Çekirdek") -> 3
I24: Hindistan | J24: =COUNTIF('Kaynak Havuzu'!D:D,"Hindistan") -> 9 | K24: =COUNTIFS('Kaynak Havuzu'!D:D,"Hindistan",'Kaynak Havuzu'!N:N,"Çekirdek") -> 4

Sheet Kaynak Havuzu
A1: ID | B1: Kapsam | C1: Bölge | D1: Ülke | E1: Kaynak | F1: URL | G1: Dil | H1: Tür | I1: Eğilim / Bağlam | J1: Güv. | K1: İçerik rolü | L1: Toplama | M1: RSS / Besleme URL | N1: Durum | O1: Not
A2: K001 | B2: A | C2: Levant & Irak | D2: Suriye | E2: Enab Baladi | F2: https://www.enabbaladi.net | G2: ar/en | H2: Bağımsız | I2: Muhalefet kökenli; sınır ekonomisi ve Türkiye'deki Suriyeliler | J2: A | K2: İç gündem + Türkiye | L2: RSS | M2: https://english.enabbaladi.net/feed/ | N2: Çekirdek | O2: Suriye çapası
A3: K002 | B3: A | C3: Levant & Irak | D3: Suriye | E3: Syria TV | F3: https://www.syria.tv | G3: ar | H3: Ana akım | I3: Katar destekli, İstanbul kökenli | J3: B | K3: İç gündem + Türkiye | L3: Scraping | N3: Çekirdek
A4: K003 | B4: A | C4: Levant & Irak | D4: Suriye | E4: SANA | F4: https://sana.sy | G4: ar/en/tr | H4: Devlet ajansı | I4: Geçiş hükümeti resmi ajansı; Türkçe edisyon | J4: C | K4: İç gündem + Türkiye | L4: RSS | M4: https://sana.sy/?feed=rss2 | N4: Çekirdek
A5: K004 | B5: A | C5: Levant & Irak | D5: Suriye | E5: Syria Direct | F5: https://syriadirect.org | G5: en/ar | H5: Bağımsız | I5: Amman; saha gazeteciliği | J5: A | K5: İç gündem + Türkiye | L5: RSS | M5: https://syriadirect.org/feed/ | N5: Çekirdek
A6: K005 | B6: A | C6: Levant & Irak | D6: Suriye | E6: North Press Agency | F6: https://npasyria.com | G6: ar/en/ku | H6: Ana akım | I6: Kamışlı; SDG bölgesi, Türkiye'ye eleştirel | J6: B | K6: İç gündem + Türkiye | L6: RSS | M6: https://npasyria.com/en/feed/ | N6: Çekirdek | O6: Kuzeydoğu perspektifi
A7: K006 | B7: A | C7: Levant & Irak | D7: Suriye | E7: Jusoor for Studies | F7: https://jusoor.co | G7: ar/en | H7: Think tank | I7: İstanbul; Türkiye–Suriye ana dosya | J7: A | K7: İç gündem + Türkiye | L7: RSS | N7: Çekirdek
A8: K007 | B8: A | C8: Levant & Irak | D8: Suriye | E8: Omran Center | F8: https://omranstudies.org | G8: ar/en | H8: Think tank | I8: İstanbul; yönetişim, ekonomi | J8: A | K8: İç gündem + Türkiye | L8: RSS | N8: Çekirdek
A9: K008 | B9: A | C9: Levant & Irak | D9: Suriye | E9: SOHR | F9: https://www.syriahr.com | G9: ar/en | H9: İzleme | I9: Rakamları doğrulamadan kullanma | J9: B | K9: İç gündem + Türkiye | L9: RSS | M9: https://www.syriahr.com/en/feed/ | N9: Kontrol et
A10: K009 | B10: A | C10: Levant & Irak | D10: Irak | E10: Rudaw | F10: https://www.rudaw.net | G10: ku/ar/en/tr | H10: Ana akım | I10: Erbil, KDP yakın; Türkçe servis | J10: B | K10: İç gündem + Türkiye | L10: RSS | M10: https://www.rudaw.net/rss/english | N10: Çekirdek | O10: Suriye Kürt dosyasını da kapsar
A11: K010 | B11: A | C11: Levant & Irak | D11: Irak | E11: Kurdistan24 | F11: https://www.kurdistan24.net | G11: ku/ar/en/tr | H11: Ana akım | I11: Erbil, KDP yakın | J11: B | K11: İç gündem + Türkiye | L11: RSS | N11: Kontrol et
A12: K011 | B12: A | C12: Levant & Irak | D12: Irak | E12: Shafaq News | F12: https://shafaq.com | G12: ar/en/ku | H12: Ana akım | I12: Erbil/Bağdat; geniş kapsam | J12: B | K12: İç gündem + Türkiye | L12: RSS | M12: https://shafaq.com/en/feed | N12: Çekirdek
A13: K012 | B13: A | C13: Levant & Irak | D13: Irak | E13: Al-Mada | F13: https://almadapaper.net | G13: ar | H13: Bağımsız | I13: Bağdat; liberal çizgi | J13: A | K13: İç gündem + Türkiye | L13: Scraping | N13: Çekirdek
A14: K013 | B14: A | C14: Levant & Irak | D14: Irak | E14: INA (Iraqi News Agency) | F14: https://ina.iq | G14: ar/en | H14: Devlet ajansı | I14: Resmi pozisyon | J14: C | K14: İç gündem + Türkiye | L14: RSS | N14: Kontrol et
A15: K014 | B15: A | C15: Levant & Irak | D15: Irak | E15: 964 Media | F15: https://964media.com | G15: ar/en | H15: Ana akım | I15: Yerel saha haberleri; Sincar, Musul | J15: B | K15: İç gündem + Türkiye | L15: RSS | N15: Çekirdek | O15: PKK/Sincar ve Kalkınma Yolu dosyaları
A16: K015 | B16: A | C16: Levant & Irak | D16: Irak | E16: Al-Sumaria | F16: https://www.alsumaria.tv | G16: ar | H16: Ana akım | I16: Bağdat TV | J16: B | K16: İç gündem + Türkiye | L16: Scraping | N16: Kontrol et
A17: K016 | B17: A | C17: Levant & Irak | D17: Irak | E17: Iraq Oil Report | F17: https://www.iraqoilreport.com | G17: en | H17: Uzman (paywall) | I17: Enerji; Kerkük–Ceyhan | J17: A | K17: İç gündem + Türkiye | L17: Gmail | N17: Kontrol et | O17: Abonelik; opsiyonel
A18: K017 | B18: R | C18: Levant & Irak | D18: Levant | E18: Al-Modon | F18: https://www.almodon.com | G18: ar | H18: Bağımsız | I18: Beyrut; Suriye-Lübnan | J18: A | K18: Bölgesel | L18: RSS | N18: Kontrol et
A19: K018 | B19: R | C19: Levant & Irak | D19: Levant | E19: L'Orient Today | F19: https://today.lorientlejour.com | G19: en/fr | H19: Ana akım | I19: Beyrut | J19: A | K19: Bölgesel | L19: RSS | N19: Kontrol et
A20: K019 | B20: A | C20: Doğu Akdeniz | D20: İsrail | E20: Times of Israel | F20: https://www.timesofisrael.com | G20: en | H20: Ana akım | I20: Merkez; Türkiye haberi yoğun | J20: B | K20: İç gündem + Türkiye | L20: RSS | M20: https://www.timesofisrael.com/feed/ | N20: Çekirdek
A21: K020 | B21: A | C21: Doğu Akdeniz | D21: İsrail | E21: Haaretz | F21: https://www.haaretz.com | G21: he/en | H21: Ana akım | I21: Sol-liberal; paywall | J21: A | K21: İç gündem + Türkiye | L21: RSS | M21: https://www.haaretz.com/srv/haaretz-latest-headlines | N21: Çekirdek
A22: K021 | B22: A | C22: Doğu Akdeniz | D22: İsrail | E22: Jerusalem Post | F22: https://www.jpost.com | G22: en | H22: Ana akım | I22: Merkez-sağ | J22: B | K22: İç gündem + Türkiye | L22: RSS | M22: https://www.jpost.com/rss/rssfeedsfrontpage.aspx | N22: Çekirdek
A23: K022 | B23: A | C23: Doğu Akdeniz | D23: İsrail | E23: Ynet | F23: https://www.ynetnews.com | G23: he/en | H23: Ana akım | I23: En yüksek tiraj | J23: B | K23: İç gündem + Türkiye | L23: RSS | M23: https://www.ynetnews.com/category/3089 | N23: Çekirdek
A24: K023 | B24: A | C24: Doğu Akdeniz | D24: İsrail | E24: Israel Hayom | F24: https://www.israelhayom.com | G24: he/en | H24: Ana akım | I24: Sağ; hükümete yakın | J24: B | K24: İç gündem + Türkiye | L24: RSS | N24: Kontrol et
A25: K024 | B25: A | C25: Doğu Akdeniz | D25: İsrail | E25: INSS | F25: https://www.inss.org.il | G25: he/en | H25: Think tank | I25: Tel Aviv; Türkiye dosyası düzenli | J25: A | K25: İç gündem + Türkiye | L25: RSS | N25: Çekirdek
A26: K025 | B26: A | C26: Doğu Akdeniz | D26: İsrail | E26: i24NEWS | F26: https://www.i24news.tv | G26: en/fr/ar | H26: Ana akım | J26: B | K26: İç gündem + Türkiye | L26: RSS | N26: Kontrol et
A27: K026 | B27: A | C27: Doğu Akdeniz | D27: Yunanistan | E27: eKathimerini | F27: https://www.ekathimerini.com | G27: en/el | H27: Ana akım | I27: Merkez-sağ, kurumsal; Türkiye haberi günlük | J27: A | K27: İç gündem + Türkiye | L27: RSS | M27: https://www.ekathimerini.com/feed/ | N27: Çekirdek | O27: Yunanistan çapası
A28: K027 | B28: A | C28: Doğu Akdeniz | D28: Yunanistan | E28: To Vima | F28: https://www.tovima.com | G28: el/en | H28: Ana akım | I28: Merkez | J28: B | K28: İç gündem + Türkiye | L28: RSS | N28: Çekirdek
A29: K028 | B29: A | C29: Doğu Akdeniz | D29: Yunanistan | E29: Proto Thema | F29: https://www.protothema.gr | G29: el/en | H29: Ana akım | I29: Popüler; Türkiye'ye sert çerçeve | J29: B | K29: İç gündem + Türkiye | L29: RSS | N29: Kontrol et | O29: Yunan kamuoyu algısı için
A30: K029 | B30: A | C30: Doğu Akdeniz | D30: Yunanistan | E30: Naftemporiki | F30: https://www.naftemporiki.gr | G30: el | H30: Ekonomi | J30: A | K30: İç gündem + Türkiye | L30: RSS | N30: Kontrol et
A31: K030 | B31: A | C31: Doğu Akdeniz | D31: Yunanistan | E31: ERT News | F31: https://www.ertnews.gr | G31: el/en | H31: Devlet yayını | J31: C | K31: İç gündem + Türkiye | L31: RSS | N31: Kontrol et
A32: K031 | B32: A | C32: Doğu Akdeniz | D32: Yunanistan | E32: ELIAMEP | F32: https://www.eliamep.gr | G32: el/en | H32: Think tank | I32: Türkiye programı var | J32: A | K32: İç gündem + Türkiye | L32: RSS | N32: Çekirdek
A33: K032 | B33: A | C33: Doğu Akdeniz | D33: Yunanistan | E33: Greek City Times | F33: https://greekcitytimes.com | G33: en | H33: Diaspora | I33: Türkiye'ye düşmanca çerçeve | J33: C | K33: İç gündem + Türkiye | L33: RSS | N33: Kontrol et | O33: Bakış açısı etiketiyle
A34: K033 | B34: A | C34: Doğu Akdeniz | D34: GKRY | E34: Cyprus Mail | F34: https://cyprus-mail.com | G34: en | H34: Ana akım | J34: A | K34: İç gündem + Türkiye | L34: RSS | M34: https://cyprus-mail.com/feed/ | N34: Çekirdek
A35: K034 | B35: A | C35: Doğu Akdeniz | D35: GKRY | E35: Philenews | F35: https://www.philenews.com | G35: el/en | H35: Ana akım | I35: En büyük gazete | J35: B | K35: İç gündem + Türkiye | L35: RSS | N35: Çekirdek
A36: K035 | B36: A | C36: Doğu Akdeniz | D36: GKRY | E36: Politis | F36: https://politis.com.cy | G36: el | H36: Ana akım | J36: B | K36: İç gündem + Türkiye | L36: RSS | N36: Kontrol et
A37: K036 | B37: A | C37: Doğu Akdeniz | D37: GKRY | E37: CNA (Cyprus News Agency) | F37: https://www.cna.org.cy | G37: el/en | H37: Devlet ajansı | J37: C | K37: İç gündem + Türkiye | L37: RSS | N37: Kontrol et
A38: K037 | B38: A | C38: Doğu Akdeniz | D38: GKRY | E38: In-Cyprus | F38: https://in-cyprus.philenews.com | G38: en | H38: Ana akım | I38: Philenews İngilizce | J38: B | K38: İç gündem + Türkiye | L38: RSS | N38: Kontrol et
A39: K038 | B39: T | C39: Doğu Akdeniz | D39: KKTC | E39: Kıbrıs Postası / Yenidüzen | F39: https://www.kibrispostasi.com | G39: tr | H39: Ana akım | I39: KKTC perspektifi | J39: B | K39: Türk perspektifi | L39: RSS | N39: Kontrol et | O39: Kıbrıs dosyası için zorunlu karşı taraf
A40: K039 | B40: A | C40: Doğu Akdeniz | D40: Mısır | E40: Mada Masr | F40: https://www.madamasr.com | G40: ar/en | H40: Bağımsız | I40: Tek bağımsız; sık engellenir | J40: A | K40: İç gündem + Türkiye | L40: RSS | M40: https://www.madamasr.com/en/feed/ | N40: Çekirdek
...

Sheet Türkiye Terimleri
A1: Dil | B1: Türkiye | C1: Ankara | D1: Erdoğan | E1: Türk (sıfat) | F1: Google News edisyonu (gl/hl/ceid) | G1: Not
A2: Arapça | B2: تركيا | C2: أنقرة | D2: أردوغان | E2: تركي / التركية | F2: SA:ar, EG:ar, LB:ar | G2: Suriye/Irak/Mısır/Körfez
A3: İbranice | B3: טורקיה | C3: אנקרה | D3: ארדואן | E3: טורקי | F3: IL:he
A4: Yunanca | B4: Τουρκία | C4: Άγκυρα | D4: Ερντογάν | E4: τουρκικός | F4: GR:el, CY:el | G4: GKRY için CY
A5: Farsça | B5: ترکیه | C5: آنکارا | D5: اردوغان | E5: ترک / ترکی | F5: — (İran edisyonu yok; AF:fa denenebilir)
A6: Azerice | B6: Türkiyə | C6: Ankara | D6: Ərdoğan | E6: türk | F6: AZ:az
A7: Ermenice | B7: Թուրքիա | C7: Անկարա | D7: Էրդողան | E7: թուրքական | F7: AM:hy
A8: Rusça | B8: Турция | C8: Анкара | D8: Эрдоган | E8: турецкий | F8: RU:ru, UA:ru, KZ:ru
A9: Ukraynaca | B9: Туреччина | C9: Анкара | D9: Ердоган | E9: турецький | F9: UA:uk
A10: İngilizce | B10: Turkey / Türkiye | C10: Ankara | D10: Erdogan | E10: Turkish | F10: US:en, GB:en, IN:en, NG:en, KE:en | G10: İki yazım da izlenmeli
A11: Almanca | B11: Türkei | C11: Ankara | D11: Erdoğan | E11: türkisch | F11: DE:de
A12: Fransızca | B12: Turquie | C12: Ankara | D12: Erdogan | E12: turc / turque | F12: FR:fr, SN:fr, DZ:fr | G12: Frankofon Afrika
A13: Çince | B13: 土耳其 | C13: 安卡拉 | D13: 埃尔多安 | E13: 土耳其的 | F13: CN:zh-Hans, HK:zh-Hant
A14: Hintçe | B14: तुर्की | C14: अंकारा | D14: एर्दोगन | E14: तुर्की | F14: IN:hi
A15: Somalice | B15: Turki | C15: Ankara | D15: Erdogan | E15: Turki | F15: — (EN kullan)
A16: Kürtçe (Kurmancî) | B16: Tirkiye / Tirkiyê | C16: Enqere | D16: Erdogan | E16: tirk | F16: — | G16: Rudaw/North Press
A17: Türkçe | B17: Türkiye | C17: Ankara | D17: Erdoğan | E17: Türk | F17: TR:tr | G17: Türk kaynaklarında ülke adıyla ters filtre
A20: Google News RSS kalıbı: https://news.google.com/rss/search?q=<terim>+when:7d&hl=<hl>&gl=<gl>&ceid=<gl>:<hl>

Sheet Tema Matrisi
A1: Tema | B1: Kapsam | C1: Hangi ülkelerde ağır | D1: Göstergeler
A2: Diplomasi | B2: Ziyaretler, anlaşmalar, forumlar, krizler | C2: Tümü | D2: Ziyaret/ay, imzalanan belge
A3: Güvenlik & savunma | B3: Operasyonlar, savunma ihracatı (SİHA, KAAN), NATO, PKK/YPG, Doğu Akdeniz askeri | C3: Suriye, Irak, Yunanistan, İsrail, Ukrayna, Azerbaycan, AB | D3: Olay sayısı, ihracat anlaşması
A4: Enerji | B4: Boru hatları, LNG, nükleer, elektrik ihracı, Doğu Akdeniz gazı | C4: Rusya, İran, Irak, Azerbaycan, İsrail, GKRY, Mısır | D4: Anlaşma, hacim
A5: Ekonomi & yatırım | B5: Ticaret, müteahhitlik, yeniden inşa, finans, Körfez sermayesi | C5: Suudi, BAE, Irak, Suriye, Rusya, Afrika | D5: Ticaret hacmi, ihale
A6: Göç & diaspora | B6: Mülteciler, geri dönüş, vize, Avrupa'daki Türkler | C6: Suriye, AB, Almanya, Yunanistan | D6: Sayılar (Göç İdaresi, UNHCR, Frontex)
A7: İç gündem (A kapsamı) | B7: Seçim, iktidar, kriz, protesto, yargı | C7: Tüm A ülkeleri | D7: LLM önem skoru ≥3
A8: Türkiye'ye bakış (B kapsamı) | B8: Yabancı basında Türkiye çerçevelemesi; olumlu/olumsuz/nötr | C8: Tüm B ülkeleri | D8: Çerçeve oranı, hacim trendi
A9: Yumuşak güç | B9: TİKA, Maarif, Diyanet, YTB, diziler, THY | C9: Afrika, Balkanlar, Orta Asya, Kafkasya | D9: Proje duyurusu
A10: Bölgesel rekabet | B10: ABD, Rusya, Çin, İran, Körfez'in Türkiye'yle etkileşimi | C10: Çapraz | D10: —
